Workbook

Sheet ReadMe
V1: Mannual | Y1: Cancer Organ Type | Z1: All Cancer | AA1: CTN | AB1: COT | AC1: CS | AF1: Cancer Organ Type | AG1: All Cancer | AH1: CTN | AI1: COT | AJ1: CS | AL1: Cancer Organ Type | AM1: All Cancer | AN1: CTN | AO1: COT | AP1: CS
A2: INDIA LAB | V2: non cancer (CON) | W2: 441 | Y2: Adnexael cancer | Z2: =SUM(AA2:AC2) -> 1 | AA2: 1 | AF2: Adnexael cancer | AG2: =SUM(AH2:AJ2) -> 1 | AH2: 1 | AL2: Adnexael cancer | AM2: =SUM(AN2:AP2) -> 0
V3: Cancer (223) | Y3: Anal canal cancer | Z3: =SUM(AA3:AC3) -> 2 | AA3: 1 | AB3: 1 | AF3: Anal canal cancer | AG3: =SUM(AH3:AJ3) -> 2 | AH3: 1 | AI3: 1 | AL3: Anal canal cancer | AM3: =SUM(AN3:AP3) -> 0
V4: CTN | W4: 101 | Y4: Bladder cancer | Z4: =SUM(AA4:AC4) -> 4 | AA4: 1 | AB4: 3 | AF4: Bladder cancer | AG4: =SUM(AH4:AJ4) -> 4 | AH4: 1 | AI4: 3 | AL4: Bladder cancer | AM4: =SUM(AN4:AP4) -> 0
A5: DNA Total | B5: =SUM(B12,E12,H12,K12,N12,Q12,T12,N14, Q14,N16,Q16) -> 804 | V5: COT | W5: 82 | Y5: Blood cancer | Z5: 14 | AA5: 3 | AB5: 5 | AC5: 5 | AF5: Blood cancer | AG5: =SUM(AH5:AJ5) -> 13 | AH5: 3 | AI5: 5 | AJ5: 5 | AL5: Blood cancer | AM5: =SUM(AN5:AP5) -> 0
V6: CS | W6: 40 | Y6: Brain cancer | Z6: =SUM(AA6:AC6) -> 2 | AA6: 1 | AB6: 1 | AF6: Brain cancer | AG6: =SUM(AH6:AJ6) -> 2 | AH6: 1 | AI6: 1 | AL6: Brain cancer | AM6: =SUM(AN6:AP6) -> 0
V7: Benign | W7: 35 | Y7: Breast cancer | Z7: 32 | AA7: 13 | AB7: 7 | AC7: 9 | AF7: Breast cancer | AG7: =SUM(AH7:AJ7) -> 29 | AH7: 13 | AI7: 7 | AJ7: 9 | AL7: Breast cancer | AM7: =SUM(AN7:AP7) -> 0
A8: INDIAN ETHNICITY | B8: =B5-B227 -> 779 | V8: HR | W8: 4 | Y8: Cervical cancer | Z8: =SUM(AA8:AC8) -> 5 | AA8: 3 | AB8: 1 | AC8: 1 | AF8: Cervical cancer | AG8: =SUM(AH8:AJ8) -> 5 | AH8: 3 | AI8: 1 | AJ8: 1 | AL8: Cervical cancer | AM8: =SUM(AN8:AP8) -> 0
V9: ND | W9: 7 | Y9: Colon cancer | Z9: =SUM(AA9:AC9) -> 15 | AA9: 7 | AB9: 4 | AC9: 4 | AD9: CRC | AF9: CRC | AG9: =SUM(AH9:AJ9) -> 40 | AH9: 15 | AI9: 16 | AJ9: 9 | AL9: Colon cancer | AM9: =SUM(AN9:AP9) -> 0
A10: Sequencing Done | V10: NDD | W10: 2 | Y10: Colo rectal cancer | Z10: =SUM(AA10:AC10) -> 5 | AA10: 2 | AB10: 2 | AC10: 1 | AF10: Eye Cancer | AG10: =SUM(AH10:AJ10) -> 1 | AH10: 1 | AL10: Colo rectal cancer | AM10: =SUM(AN10:AP10) -> 0
V11: D | W11: 98 | Y11: Eye Cancer | Z11: =SUM(AA11:AC11) -> 1 | AA11: 1 | AF11: Gall bladder cancer | AG11: =SUM(AH11:AJ11) -> 1 | AH11: 1 | AL11: Esophagus cancer | AM11: =SUM(AN11:AP11) -> 0
A12: CONTROL | B12: =COUNTA(CONTROLS[Sr.no]) -> 431 | D12: CTN | E12: =COUNTA(CTN[Sr.no]) -> 101 | G12: COT | H12: =COUNTA(COT[Sr.no]) -> 79 | J12: CS | K12: =COUNTA(CS[Sr.no]) -> 40 | M12: Benign | N12: =COUNTA(Benign[Sr.no]) -> 34 | P12: High Risk | Q12: =COUNTA(HR[Sr.no]) -> 4 | S12: Diabetes | T12: =COUNTA(Diabetes[Sr.no]) -> 104 | V12: TOTAL | W12: =SUM(W2:W11) -> 810 | Y12: Esophagus cancer | Z12: =SUM(AA12:AC12) -> 3 | AA12: 1 | AB12: 2 | AD12: Gastroesophegial cancer | AF12: Gastroesophegial cancer | AG12: =SUM(AH12:AJ12) -> 6 | AH12: 3 | AI12: 3 | AL12: Gall bladder cancer | AM12: =SUM(AN12:AP12) -> 0
A13: AGE | B13: Total | D13: AGE | E13: Total | G13: AGE | H13: Total | J13: AGE | K13: Total | Y13: Gall bladder cancer | Z13: =SUM(AA13:AC13) -> 1 | AA13: 1 | AF13: Head and Neck cancer | AG13: =SUM(AH13:AJ13) -> 15 | AH13: 9 | AI13: 5 | AJ13: 1 | AL13: Gastroesophegial cancer | AM13: =SUM(AN13:AP13) -> 0
A14: 18 to 30 | B14: =COUNTA(CONTROL_1_30[Sample]) -> 119 | D14: 18 to 30 | E14: =COUNTA(CTN_1_30[Sample]) -> 2 | G14: 18 to 30 | H14: =COUNTA(COT_1_30[Sample]) -> 4 | J14: 18 to 30 | K14: =COUNTA(CS_1_30[Sample]) -> 4 | M14: Screening | N14: =COUNTIF('India_lab_(duplicate)'!H2:H979,"Screening") -> 0 | P14: ND | Q14: =COUNTIF(India_Lab!H2:H979,"ND") -> 7 | Y14: Gastroesophegeal cancer | Z14: =SUM(AA14:AC14) -> 3 | AA14: 2 | AB14: 1 | AF14: Liver cancer | AG14: =SUM(AH14:AJ14) -> 5 | AH14: 5 | AL14: Hepatocellular carcinoma | AM14: =SUM(AN14:AP14) -> 0
A15: 31 to 60 | B15: =COUNTA(CONTROL_31_60[Sample]) -> 257 | D15: 31 to 60 | E15: =COUNTA(CTN_31_60[Sample]) -> 53 | G15: 31 to 60 | H15: =COUNTA(COT_31_60[Sample]) -> 36 | J15: 31 to 60 | K15: =COUNTA(CS_31_60[Sample]) -> 19 | Y15: Head and Neck cancer | Z15: =SUM(AA15:AC15) -> 2 | AA15: 2 | AD15: Head and neck | AF15: Lung cancer | AG15: =SUM(AH15:AJ15) -> 40 | AH15: 20 | AI15: 18 | AJ15: 2 | AL15: Liver cancer | AM15: =SUM(AN15:AP15) -> 0
A16: 60+ | B16: =COUNTA(CONTROL_61_Plus[Sample]) -> 54 | D16: 61 + | E16: =COUNTA(CTN_61_Plus[Sample]) -> 46 | G16: 60+ | H16: =COUNTA(COT_61_Plus[Sample]) -> 39 | J16: 60+ | K16: =COUNTA(CS_61_Plus[Sample]) -> 17 | M16: NDD | N16: =COUNTIF('India_lab_(duplicate)'!H2:H768,"NDD") -> 2 | P16: ? | Q16: =COUNTIF('India_lab_(duplicate)'!H2:H979,"Unavailable") -> 2 | Y16: Hepatocellular carcinoma | Z16: =SUM(AA16:AC16) -> 1 | AA16: 1 | AD16: Liver cancer | AF16: Ovarian cancer | AG16: =SUM(AH16:AJ16) -> 5 | AH16: 1 | AI16: 4 | AL16: Lung cancer | AM16: =SUM(AN16:AP16) -> 0
A17: Total samples | B17: =SUM(B14:B16) -> 430 | D17: Total samples | E17: =SUM(E14:E16) -> 101 | G17: Total samples | H17: =SUM(H14:H16) -> 79 | J17: Total samples | K17: =SUM(K14:K16) -> 40 | Y17: Liver cancer | Z17: =SUM(AA17:AC17) -> 4 | AA17: 4 | AF17: Perianal Cancer | AG17: =SUM(AH17:AJ17) -> 1 | AI17: 1 | AL17: Nasopharynx cancer | AM17: =SUM(AN17:AP17) -> 0
Y18: Lung cancer | Z18: 41 | AA18: 19 | AB18: 18 | AC18: 2 | AF18: Pancreas cancer | AG18: =SUM(AH18:AJ18) -> 6 | AH18: 1 | AI18: 3 | AJ18: 2 | AL18: Oral cancer | AM18: =SUM(AN18:AP18) -> 0
Y19: Nasopharynx cancer | Z19: =SUM(AA19:AC19) -> 1 | AA19: 1 | AF19: Prostate cancer | AG19: =SUM(AH19:AJ19) -> 23 | AH19: 15 | AI19: 5 | AJ19: 3 | AL19: Ovarian cancer | AM19: =SUM(AN19:AP19) -> 0
A20: AGE - GENDER Distribution ( Excluding Other Ethnicity) | Y20: Oral cancer | Z20: =SUM(AA20:AC20) -> 6 | AA20: 4 | AB20: 2 | AF20: PUO | AG20: =SUM(AH20:AJ20) -> 1 | AH20: 1 | AL20: Pancreas cancer | AM20: =SUM(AN20:AP20) -> 0
Y21: Ovarian cancer | Z21: =SUM(AA21:AC21) -> 5 | AA21: 1 | AB21: 4 | AF21: Sarcoma | AG21: =SUM(AH21:AJ21) -> 2 | AH21: 1 | AI21: 1 | AL21: Prostate cancer | AM21: =SUM(AN21:AP21) -> 0
A22: CONTROL | Y22: Perianal Cancer | Z22: =SUM(AA22:AC22) -> 1 | AB22: 1 | AF22: Stomach cancer | AG22: =SUM(AH22:AJ22) -> 4 | AH22: 3 | AJ22: 1 | AL22: PUO | AM22: =SUM(AN22:AP22) -> 0
A23: AGE | B23: Male | C23: Femaie | D23: Total samples | Y23: Pancreas cancer | Z23: =SUM(AA23:AC23) -> 6 | AA23: 1 | AB23: 3 | AC23: 2 | AF23: Testicular cancer | AG23: =SUM(AH23:AJ23) -> 4 | AI23: 2 | AJ23: 2 | AL23: Rectal cancer | AM23: =SUM(AN23:AP23) -> 0
A24: 18 to 30 | B24: =COUNTIFS('India_lab_(duplicate)'!H:H,"CON", 'India_lab_(duplicate)'!E:E,">=1", 'India_lab_(duplicate)'!E:E,"<=30", 'India_lab_(duplicate)'!F:F,"Male", 'India_lab_(duplicate)'!J:J,"<>*other ethnicity*") -> 66 | C24: =COUNTIFS('India_lab_(duplicate)'!H:H,"CON", 'India_lab_(duplicate)'!E:E,">=1", 'India_lab_(duplicate)'!E:E,"<=30", 'India_lab_(duplicate)'!F:F,"Female", 'India_lab_(duplicate)'!J:J,"<>*other ethnicity*") -> 53 | D24: =SUM(B24:C24) -> 119 | Y24: Prostate cancer | Z24: =SUM(AA24:AC24) -> 23 | AA24: 15 | AB24: 5 | AC24: 3 | AF24: Thyroid cancer | AG24: =SUM(AH24:AJ24) -> 2 | AH24: 2 | AL24: Rectum cancer | AM24: =SUM(AN24:AP24) -> 0
A25: 31 to 60 | B25: =COUNTIFS('India_lab_(duplicate)'!H:H,"CON", 'India_lab_(duplicate)'!E:E,">=31", 'India_lab_(duplicate)'!E:E,"<=60", 'India_lab_(duplicate)'!F:F,"Male", 'India_lab_(duplicate)'!J:J,"<>*other ethnicity*") -> 131 | C25: =COUNTIFS('India_lab_(duplicate)'!H:H,"CON", 'India_lab_(duplicate)'!E:E,">=31", 'India_lab_(duplicate)'!E:E,"<=60", 'India_lab_(duplicate)'!F:F,"Female", 'India_lab_(duplicate)'!J:J,"<>*other ethnicity*") -> 110 | D25: =SUM(B25:C25) -> 241 | Y25: PUO | Z25: =SUM(AA25:AC25) -> 1 | AA25: 1 | AF25: Gastrointestinal cancer | AG25: =SUM(AH25:AJ25) -> 2 | AI25: 2 | AL25: Sarcoma | AM25: =SUM(AN25:AP25) -> 0
A26: 60+ | B26: =COUNTIFS('India_lab_(duplicate)'!H:H,"CON", 'India_lab_(duplicate)'!E:E,">=61", 'India_lab_(duplicate)'!F:F,"Male", 'India_lab_(duplicate)'!J:J,"<>*other ethnicity*") -> 30 | C26: =COUNTIFS('India_lab_(duplicate)'!H:H,"CON", 'India_lab_(duplicate)'!E:E,">=61", 'India_lab_(duplicate)'!F:F,"Female", 'India_lab_(duplicate)'!J:J,"<>*other ethnicity*") -> 20 | D26: =SUM(B26:C26) -> 50 | Y26: Rectal cancer | Z26: =SUM(AA26:AC26) -> 1 | AB26: 1 | AF26: Kidney cancer | AG26: =SUM(AH26:AJ26) -> 4 | AI26: 2 | AJ26: 2 | AL26: Stomach cancer | AM26: =SUM(AN26:AP26) -> 0
A27: Total samples | B27: =SUM(B24:B26) -> 227 | C27: =SUM(C24:C26) -> 183 | Y27: Rectum cancer | Z27: =SUM(AA27:AC27) -> 19 | AA27: 6 | AB27: 9 | AC27: 4 | AF27: Perihilar cholangiocarcinoma | AG27: =SUM(AH27:AJ27) -> 1 | AI27: 1 | AL27: Testicular cancer | AM27: =SUM(AN27:AP27) -> 0
Y28: Sarcoma | Z28: =SUM(AA28:AC28) -> 2 | AA28: 1 | AB28: 1 | AF28: Endometrial cancer | AG28: =SUM(AH28:AJ28) -> 1 | AJ28: 1 | AL28: Thyroid cancer | AM28: =SUM(AN28:AP28) -> 0
Y29: Stomach cancer | Z29: =SUM(AA29:AC29) -> 4 | AA29: 3 | AC29: 1 | AF29: Uterine Carcinosarcoma | AG29: =SUM(AH29:AJ29) -> 1 | AJ29: 1 | AL29: Tongue cancer | AM29: =SUM(AN29:AP29) -> 0
A30: CANCER | Y30: Testicular cancer | Z30: =SUM(AA30:AC30) -> 4 | AB30: 2 | AC30: 2 | AF30: Neuroendocrine Gland cancer | AG30: =SUM(AH30:AJ30) -> 1 | AJ30: 1 | AL30: Gastrointestinal cancer | AM30: =SUM(AN30:AP30) -> 0
Y31: Thyroid cancer | Z31: =SUM(AA31:AC31) -> 2 | AA31: 2 | AF31: ND | AG31: =SUM(AH31:AJ31) -> 1 | AI31: 1 | AL31: Intestine cancer | AM31: =SUM(AN31:AP31) -> 0
A32: AGE | B32: Male | C32: Female | D32: Total samples | Y32: Tongue cancer | Z32: =SUM(AA32:AC32) -> 2 | AA32: 2 | AF32: Total | AG32: =SUM(AG2:AG31) -> 223 | AH32: =SUM(AH2:AH31) -> 101 | AI32: =SUM(AI2:AI31) -> 82 | AJ32: =SUM(AJ2:AJ31) -> 40 | AL32: Kidney cancer | AM32: =SUM(AN32:AP32) -> 0
A33: 18 to 30 | B33: =SUM(B138,H138,M138) -> 7 | C33: =SUM(C138,I138,N138) -> 3 | D33: =SUM(B33:C33) -> 10 | Y33: Gastrointestinal cancer | Z33: =SUM(AA33:AC33) -> 1 | AB33: 1 | AD33: Gastrointestinal cancer | AL33: Perihilar cholangiocarcinoma | AM33: =SUM(AN33:AP33) -> 0
A34: 31 to 60 | B34: =SUM(B139,H139,M139) -> 46 | C34: =SUM(C139,I139,N139) -> 56 | D34: =SUM(B34:C34) -> 102 | Y34: Intestine cancer | Z34: =SUM(AA34:AC34) -> 1 | AB34: 1 | AL34: Salivary Gland cancer | AM34: =SUM(AN34:AP34) -> 0
A35: 61 + | B35: =SUM(B140,H140,M140) -> 48 | C35: =SUM(C140,I140,N140) -> 43 | D35: =SUM(B35:C35) -> 91 | Y35: Kidney cancer | Z35: =SUM(AA35:AC35) -> 4 | AB35: 2 | AC35: 2 | AL35: Endometrial cancer | AM35: =SUM(AN35:AP35) -> 0
A36: Total samples | B36: =SUM(B33:B35) -> 101 | C36: =SUM(C33:C35) -> 102 | Y36: Perihilar cholangiocarcinoma | Z36: =SUM(AA36:AC36) -> 1 | AB36: 1 | AL36: Follicular ameloblastoma | AM36: =SUM(AN36:AP36) -> 0
Y37: Salivary Gland cancer | Z37: =SUM(AA37:AC37) -> 3 | AB37: 3 | AL37: Uterine carcinosarcoma | AM37: =SUM(AN37:AP37) -> 0
Y38: Endometrial cancer | Z38: =SUM(AA38:AC38) -> 1 | AC38: 1 | AL38: ND | AM38: =SUM(AN38:AP38) -> 0
A39: Cancer types | Y39: Follicular ameloblastoma | Z39: =SUM(AA39:AC39) -> 1 | AC39: 1 | AL39: Total | AM39: =SUM(AM2:AM38) -> 0
Y40: Uterine Carcinosarcoma | Z40: =SUM(AA40:AC40) -> 1 | AC40: 1
...

Sheet India_Lab
A1: l | B1: AOB ID | C1: SID | D1: Name | E1: Age | F1: Gender | G1: Patient ID | H1: New Case label | I1: Additional | J1: Source | K1: Detail Disease | L1: Organ Type | M1: Comorbidity | N1: Family history | O1: Metastasis | P1: Patient status | Q1: Sample Collection Date | R1: DNA availability | S1: Sequencing | T1: DIN | U1: Research/Report | V1: Sequencing partner (E) | W1: Data received (E) | X1: TMR-E (Gbp) | Y1: Data analysed-E (Som) | Z1: Data analysed-E (Germ) | AA1: Sample lebeling | AB1: Analysis | AC1: Report (made/release) | AD1: Report Release Date | AE1: Comments (report sample ID) | AF1: Consultation
B2: 2022-2025 | AB2: - | AC2: -
A3: 1 | B3: 6 | C3: 6 | D3: Sujay | E3: 50 | F3: Male | G3: NA | H3: CON | N3: - | O3: - | Q3: - | R3: Exhausted | S3: Done | T3: - | U3: Research | V3: Medgenome | W3: - | X3: 122.16 (18.44) | Y3: Yes | Z3: - | AA3: 6b | AB3: - | AC3: -
A4: 2 | B4: 9 | C4: 1A0027 | D4: Jyoti Pujari | E4: 45 | F4: Female | G4: J000019 | H4: CON | M4: - | N4: - | O4: - | Q4: 44698 | R4: Exhausted | S4: Done | T4: - | U4: Research | V4: Medgenome | W4: - | X4: 79.99 (12) | Y4: Yes | Z4: Yes | AA4: 9b | AB4: - | AC4: -
A5: 3 | B5: 11 | C5: 1A0029 | D5: Priya Parsekar | E5: >45 | F5: Female | G5: P000004 | H5: CON | M5: - | N5: - | O5: - | Q5: 44698 | R5: Exhausted | S5: Done | T5: - | U5: Research | V5: Medgenome | W5: - | X5: 81.29 (12.2) | Y5: Yes | Z5: Yes | AA5: 11b, 11d | AB5: - | AC5: -
A6: 4 | B6: 14 | C6: 1A0041 | D6: Neepa dalal | E6: 52 | F6: Female | G6: N000002 | H6: CON | M6: - | N6: Diabetes, Thyroid, Osteoporosis & Parents have diabetes, heart diseases and cancer | O6: - | Q6: 44701 | R6: Exhausted | S6: Done | T6: - | U6: Research | V6: Medgenome | W6: - | X6: 77.41 (11.6) | Y6: Yes | Z6: Yes | AA6: 14b, 14d | AB6: - | AC6: -
A7: 5 | B7: 24 | C7: 1A0061 | D7: Rita Gurwada | E7: 63 | F7: Female | G7: R000005 | H7: CON | M7: - | N7: - | O7: - | Q7: 44711 | R7: Exhausted | S7: Done | T7: 8.4 | U7: Research | V7: Medgenome | W7: - | X7: 59.75 (9) | Y7: Yes | Z7: Yes | AA7: 24b, 24d | AB7: - | AC7: -
A8: 6 | B8: 27 | C8: 1A0154 | D8: Kapil Agarwal | E8: 38 | F8: Male | G8: K000006 | H8: CON | M8: - | N8: T.N Breast Cancer (Mother) | O8: - | Q8: 44770 | R8: Exhausted | S8: Done | T8: 8.4 | U8: Research | V8: Medgenome | W8: - | X8: 56.16 (8.4) | Y8: Yes | Z8: Yes | AA8: 27b | AB8: - | AC8: -
A9: 7 | B9: 32 | C9: 1A0166 | D9: Leela E. Shinde | E9: 62 | F9: Female | G9: L000003 | H9: CON | M9: - | N9: - | O9: - | Q9: 44796 | R9: Exhausted | S9: Done | T9: 8.5 | U9: Research | V9: Medgenome | W9: - | X9: 73.19 (11) | Y9: Yes | Z9: Yes | AA9: 32b, 32d | AB9: - | AC9: -
A10: 8 | B10: 34 | C10: 1A0169 | D10: Nitu Kumari | E10: 35 | F10: Female | G10: N000010 | H10: CON | M10: - | N10: - | O10: - | Q10: 44798 | R10: Exhausted | S10: Done | T10: 8.3 | U10: Research | V10: Medgenome | W10: - | X10: 66.55 (10) | Y10: Yes | Z10: Yes | AA10: 34b, 34d | AB10: - | AC10: -
A11: 9 | B11: 36 | C11: 1A0168 | D11: Pramod Shinde | E11: 37 | F11: Male | G11: P000015 | H11: CON | M11: - | N11: Cancer-Family History | O11: - | Q11: 44796 | R11: Exhausted | S11: Done | T11: 8.6 | U11: Research | V11: Medgenome | W11: - | X11: 59.43 (8.8) | Y11: Yes | Z11: Yes | AA11: 36b | AB11: - | AC11: -
A12: 10 | B12: 37 | C12: 1A0159 | D12: Satish Shukla | E12: 35 | F12: Male | G12: S000040 | H12: CON | M12: - | N12: - | O12: - | Q12: 44781 | R12: Exhausted | S12: Done | T12: 8.2 | U12: Research | V12: Medgenome | W12: - | X12: 73.78 (11) | Y12: Yes | Z12: - | AA12: 37b | AB12: - | AC12: -
A13: 11 | B13: 38 | C13: 1A0155 | D13: Rohit Kachroo | E13: 50 | F13: Male | G13: R000010 | H13: CON | M13: - | N13: - | O13: - | Q13: - | R13: Exhausted | S13: Done | T13: 9.6 | U13: Research | V13: Medgenome | W13: - | X13: 75.18 (11.2) | Y13: Yes | Z13: Yes | AA13: 38b, 38d | AB13: - | AC13: -
A14: 12 | B14: 43 | C14: 1A0347 | D14: V Krishnan | E14: 52 | F14: Male | G14: K000017 | H14: CON | I14: Elevated PSA | M14: PSA high | N14: - | O14: - | Q14: - | R14: Exhausted | S14: Done | T14: 8.3 | U14: Report | V14: Medgenome | W14: - | X14: 72.92 (11) | Y14: Yes | Z14: Yes | AA14: 43b, 43d | AB14: - | AC14: -
A15: 13 | B15: 44 | C15: 1A0348 | D15: Aparna | E15: 55 | F15: Female | G15: A000045 | H15: CON | N15: - | O15: - | Q15: 44875 | R15: Exhausted | S15: Done | T15: 8.3 | U15: Research | V15: Medgenome | W15: - | X15: 53.31 (8) | Y15: Yes | Z15: Yes | AA15: 44b, 44d | AB15: - | AC15: -
A16: 14 | B16: 56 | C16: 1A0458 | D16: Gunjan Bajpai | E16: 42 | F16: Female | G16: G000012 | H16: CON | M16: - | N16: Diabetes | O16: - | Q16: 44905 | R16: YES | S16: Done | T16: 8.5 | U16: Research | V16: Medgenome | W16: - | X16: 39.11 (5.8) | Y16: Yes | Z16: Yes | AA16: 56b, 56d_R | AB16: - | AC16: -
A17: 15 | B17: 57 | C17: 1A0459 | D17: Amit Bajpai | E17: 47 | F17: Male | G17: A000054 | H17: CON | M17: - | N17: Diabetes | O17: - | Q17: 44905 | R17: YES | S17: Done | T17: 8.6 | U17: Research | V17: Medgenome | W17: - | X17: 87.84 (13.2) | Y17: Yes | Z17: Yes | AA17: 57b, 57d_R | AB17: - | AC17: -
A18: 16 | B18: 77 | C18: 2A0027 | D18: Meena Sawant | E18: 57 | F18: Female | G18: M000034 | H18: CON | M18: - | N18: - | O18: - | Q18: 44933 | R18: YES | S18: Done | T18: 8.8 | U18: Research | V18: Medgenome | W18: - | X18: 56.56 (8.4) | Y18: Yes | Z18: Yes | AA18: 77b, 77d | AB18: - | AC18: -
A19: 17 | B19: 91 | C19: 2A0087 | D19: Dr G. S. Toteja | E19: 64 | F19: Male | G19: T000013 | H19: CON | M19: - | N19: - | O19: - | Q19: 44942 | R19: YES | S19: Done | T19: 8.2 | U19: Research | V19: Medgenome | W19: - | X19: 103.48 () | Y19: Yes | Z19: Yes | AA19: 91b, 91d | AB19: - | AC19: -
A20: 18 | B20: 136 | C20: 2A0440 | D20: Neha Ajay Hirlekar | E20: 39 | F20: Female | G20: N000044 | H20: CON | M20: - | N20: Her Grandfather (mother side), Uncle (mother side) | O20: - | Q20: 0 | R20: YES | S20: Done | T20: - | U20: Research | V20: Medgenome | W20: 45076 | X20: 79.14 (11.8) | Y20: Yes | Z20: - | AA20: 136d/148d | AB20: - | AC20: -
A21: 19 | B21: 89 | C21: 2A0057 | D21: Amruta Ghag | E21: 62 | F21: Female | G21: A000062 | H21: CON | M21: - | N21: Diabetes and HTN; Mother- colon cancer; Brother-pancreas | O21: - | Q21: 44936 | R21: YES | S21: Done | T21: 8.3 | U21: Research | V21: Medgenome | W21: 45076 | X21: 68.68 (10.2) | Y21: Yes | Z21: Yes | AA21: - | AB21: - | AC21: -
A22: 20 | B22: 161 | C22: 2A0760 | D22: Radhika Radia | E22: 46 | F22: Female | G22: R000022 | H22: CON | M22: - | N22: Brother- Prostate Cancer | O22: - | Q22: 45145 | R22: YES | S22: Done | T22: 8.5 | U22: Research | V22: Medgenome | W22: 45169 | X22: 59.6 (8.8) | Y22: Yes | Z22: Yes | AA22: 161b, 161d | AB22: Yes | AC22: -
A23: 21 | B23: 166 | C23: 2A1063 | D23: Ravikant Ruia | E23: 74 | F23: Male | G23: R000075 | H23: Benign | I23: Screening | K23: Male Reproductive Organ (Prostate, BPH), Multiple benign cystic lesions | L23: Prostate | M23: Adenomatous prostate hyperplasia with multiple benign cystic lesions | N23: Clinical history of patient - Adenomatous prostate hyperplasia with multiple benign cystic lesions (MRI, dated 23/1/218) and benign prostate hyperplasia (MRI, dated 14/9/219); Serum PSA: 1.16 ng/mL, dated 11/11/223; Serum cancer marker: AFP-α, CA15.3, CA19.9, CEA & Thyroglobulin (All in normal range), dated 11/11/223; On hormone therapy: past 2-3 years. Family history of cancer - Brother: Lung Cancer, Sister: Myelodysplastic syndrome, Sister: Cancer (type not provided)._x000D_ | O23: - | Q23: 45241 | R23: YES | S23: Done | T23: 8.5 | U23: Report | V23: Medgenome | W23: 45265 | X23: 61.67 (9.2) | Y23: Yes | Z23: Yes | AA23: 166b, 166d | AB23: Yes | AC23: Released | AD23: 45275 | AE23: 3A0724
A24: 22 | B24: 167 | C24: 2A1100 | D24: Madhu Ruia | E24: 68 | F24: Female | G24: M000094 | H24: Benign | K24: Hepatobilliary System (Liver, Hemangioma) | L24: Liver | M24: - | N24: Clinical history of patient - Hemangioma in liver (Report not provided). On hormone therapy (Estrogen/Progesterone). Cancer serum marker done (Report not provided). Tonsillectomy at the age of 11/12 years. | O24: - | Q24: 45253 | R24: YES | S24: Done | T24: 8.9 | U24: Report | V24: Medgenome | W24: 45280 | X24: 78.99 (11.8) | Y24: Yes | Z24: Yes | AA24: 167b, 167d | AB24: Yes | AC24: Released | AD24: 45294 | AE24: 3A0860
A25: 23 | B25: 163 | C25: 2A0810 | D25: Bhavna Roy | E25: 56 | F25: Female | G25: B000032 | H25: CON | M25: - | N25: - | O25: - | Q25: 45161 | R25: YES | S25: Done | T25: 9.1 | U25: Research | V25: Medgenome | W25: 45183 | X25: 57.19 (8.6) | Y25: Yes | Z25: Yes | AA25: 163b, 163d | AB25: - | AC25: -
A26: 24 | B26: 189 | C26: 3A0326 | D26: Kavita Nalawade | E26: 25 | F26: Female | G26: K000010 | H26: CON | M26: - | N26: Father- cancer | O26: - | Q26: 45357 | R26: YES | S26: Done | T26: 8.9 (100X) | U26: Research | V26: Medgenome | W26: 45398 | X26: 61.28 (9.2) | Y26: Yes | Z26: - | AA26: 189b, 189d | AB26: Yes | AC26: -
A27: 25 | B27: 19 | C27: 3A0350 | D27: Dheeraj Ahluwalia | E27: 56 | F27: Male | G27: D000071 | H27: Benign | I27: Enlarged prostate | K27: BPH | L27: Prostate | M27: Diabetes, cholesterol, enlarged prostate | N27: Family history of cancer: Father - Brain cancer at 79 Years, Paternal Grandfather - Blood cancer at 78 Years; Other health conditions (Current Medications): Elevated cholesterol (Lipitor), Diabetes (Linagliptin, Empagliflozin, Glucophage XR), Enlarged prostrate (Tamsulosin Hydrochloride) | O27: - | Q27: 45369 | R27: YES | S27: Done | T27: 9.2 (250X) | U27: Report | V27: Medgenome | W27: 45411 | X27: 62.6 (9.4) | Y27: Yes | Z27: Yes | AA27: 190b, 190d | AB27: Yes | AC27: Released | AD27: 45416
A28: 26 | B28: 192 | C28: 3A0454 | D28: Mehar Bajaj | E28: 27 | F28: Female | G28: M000132 | H28: CON | M28: - | N28: Clinical history of patient: No relevant clinical history of concern. Family history of cancer: Maternal Grandfather - Lung cancer at age of 7 years, Maternal great grandfather and great grandmother - Ear cancer | O28: - | Q28: 45390 | R28: YES | S28: Done | T28: 8.7 (250X) | U28: Report | V28: Medgenome | W28: 45427 | X28: 156.79 (23.6) | Y28: Yes | Z28: Yes | AA28: 192b, 192d | AB28: - | AC28: Released | AD28: 45435 | AE28: 3A1080
A29: 27 | B29: 21 | C29: 3A0631 | D29: Nirali Gurwada | E29: 40 | F29: Female | G29: N000092 | H29: CON | M29: - | N29: - | O29: - | Q29: 45454 | R29: YES | S29: Done | T29: 8.2 (250X) | U29: Report | V29: Medgenome | W29: 45482 | X29: 193.85 (29.2) | Y29: Yes | Z29: Yes | AA29: 201b, 201d | AB29: Yes | AC29: -
A30: 28 | B30: 24 | C30: 3A0700 | D30: Vijay Shah | E30: 67 | F30: Male | G30: V000001 | H30: CON | M30: Diabetes, hypertension | N30: Clinical history of patient • Diabetes and high BP in the last 1 year: On Rx drug for 4 months, now stopped. • Sudden transient rise in BP in working hours 4 months back, high CPK MB levels: 2 U/I in blood dated 17th Apr 224, HS troponin 1 level is in normal range dated 17th Apr 224 • Smoking since last 1 years: 2-3 per day and occasional drinking (stopped from the last 2 months) • Supplements: - Formula 1 from HERBALIFE - Personalised Protein powder, shakes, nutritional supplements, cell activator tablets (Antioxidant/ Alpha-lipoic acid tablet) as a meal replacement; Probiotics (Bacillus Coagulans) for gut health; XAR- XAP 2 times a day daily Family history of cancer • NA | O30: - | Q30: 45472 | R30: YES | S30: Done | T30: 8.6 (100X) | U30: Report | V30: Medgenome | W30: 45510 | X30: 69.62 (10.4) | Y30: Yes | Z30: Yes | AA30: 204b, 204d | AB30: - | AC30: Released | AD30: 45455
A31: 29 | B31: 25 | C31: 3A0723 | D31: Shweta Devendra | E31: 26 | F31: Female | G31: S000411 | H31: CON | M31: - | N31: - | O31: - | Q31: 45478 | R31: YES | S31: Done | T31: 8.4 (100X) | U31: Research | V31: Medgenome | W31: 45516 | X31: 80.46 (12) | Y31: Yes | Z31: Yes | AA31: 205b, 205d | AB31: Yes | AC31: -
A32: 30 | B32: 29 | C32: 3A0753 | D32: Shailesh HariBhakti | E32: 68 | F32: Male | G32: S000221 | H32: CON | M32: Diabetes, Heart disease | N32: Clinical History  Bypass surgery in 24, pacemaker in 222, both eyes cataract surgery  Diabetes-taking insulin (dose was titrating based on sugar level)  XAR-XAP for last 5 years (dose: during covid 3 times each/day, now once/day); Nova rapid bulds; Shelcal 5; Galvin met 5/5; Rozuvas cv Seloken XL 12.5 mg Family history of cancer  Mother- diabetes, cardiovascular problem | O32: - | Q32: 45484 | R32: YES | S32: Done | T32: 7.9 (250X) | U32: Report | V32: Medgenome | W32: 45511 | X32: 160.7 (24.2) | Y32: Yes | Z32: Yes | AA32: 209b, 209d | AB32: Yes | AC32: Released | AD32: 24/09/2024
A33: 31 | B33: 213 | C33: 3A0819 | D33: Niteen Tulpule | E33: 50 | F33: Male | G33: N000101 | H33: CON | M33: Hypertension | Q33: 45496 | R33: YES | S33: Done | T33: 8.4 (250X) | U33: Report | V33: Medgenome | W33: 45561 | X33: 132.77 (20) | Y33: Yes | Z33: Yes | AA33: 213b, 213d | AB33: - | AC33: Released | AD33: 45422
A34: 32 | B34: 249 | C34: 3A1093 | D34: Kavita Singh | E34: 59 | F34: Female | G34: K000101 | H34: D | J34: Dr Nadeem | M34: - | Q34: 45587 | R34: YES | S34: Done | T34: 8.6 | U34: Report | V34: Medgenome | W34: 45624 | X34: 69.64 (10.4) | Y34: Yes | Z34: Yes | AA34: 249b, 249d | AB34: Yes | AC34: -
A35: 33 | B35: 276 | C35: 3A1167 | D35: Mahesh Agrawal | E35: 73 | F35: Male | G35: M000008 | H35: Benign | K35: Male Reproductive Organ (Benign Prostate Hyperplasia), exophytic cyst in the upper pole of left kidney | L35: Prostate, kidney | M35: Hypothyroidism | Q35: 45610 | R35: YES | S35: Done | T35: - | U35: Paid Report | V35: Medgenome | W35: 45690 | X35: 155.86 (23.4) | Y35: Yes | Z35: Yes | AA35: 276b, 276d | AB35: - | AC35: Released | AD35: 45677 | AE35: 3A1108
A36: 34 | B36: 31 | C36: 3A1248 | D36: Ashish Gupta | E36: 26 | F36: Male | G36: A000300 | H36: D | J36: Dr Nadeem | M36: Diabetes | Q36: 45624 | R36: YES | S36: Done | T36: 9.1 | U36: Research | V36: Medgenome | W36: 45677 | X36: 79.48 (12) | Y36: Yes | Z36: Yes | AA36: 301b, 301d | AB36: Yes | AC36: -
A37: 35 | B37: 322 | C37: 3A1288 | D37: Shiv Nayak | E37: 64 | F37: Male | G37: S000506 | H37: CON | M37: - | Q37: 45635 | R37: YES | S37: Done | T37: 7.9 | U37: Report | V37: Medgenome | W37: 45677 | X37: 63.6 (9.6) | Y37: Yes | Z37: Yes | AA37: 322b, 322d | AB37: Yes | AC37: Released | AD37: 45678
A38: 36 | B38: 359 | C38: 3A1342 | D38: Komal Dharmani | E38: 44 | F38: Female | G38: K000114 | H38: Benign | K38: Female Reproductive Organ (Endometriosis and Uterine Fibroids) | L38: Uterus | M38: Endometriosis, fibroid surgery in 2019 | Q38: 45645 | R38: YES | S38: Done | T38: 7.7 | U38: Report | V38: Medgenome | W38: 45692 | X38: 76.31 (11.4) | Y38: Yes | Z38: Yes | AA38: 359b, 359d | AB38: Yes | AC38: Released | AD38: 45706 | AE38: 3A1273
A39: 37 | B39: 36 | C39: 3A1343 | D39: Lalit Dharmani | E39: 49 | F39: Male | G39: L000039 | H39: CON | M39: - | Q39: 45645 | R39: YES | S39: Done | T39: 8.2 | U39: Report | V39: Medgenome | W39: 45692 | X39: 66.55 (10) | Y39: Yes | Z39: Yes | AA39: 360b, 360d | AB39: Yes | AC39: Released | AD39: 45706
A40: 38 | C40: 4A0414 | D40: Arun Madhu | E40: 40 | F40: Male | G40: A000355 | H40: CON | M40: Bradycardia, Sleep apnoea | Q40: 45717 | R40: YES | S40: Done | T40: - | U40: Research | V40: MiBiome | W40: 45832 | X40: 66.84 (10) | Y40: Yes | Z40: - | AA40: 4A0414 | AB40: - | AC40: -
...

Sheet India_lab_(duplicate)
A1: Sr no | B1: AOB ID | C1: SID | D1: Name | E1: Age | F1: Gender | G1: Patient ID | H1: New Case label | I1: Additional | J1: Source | K1: Detail Disease | L1: Organ Type | M1: Comorbidity | N1: Family history | O1: Metastasis | P1: Patient status | Q1: Sample Collection Date | R1: DNA availability | S1: Sequencing | T1: DIN | U1: Research/Report | V1: Sequencing partner (E) | W1: Data received (E) | X1: TMR-E (Gbp) | Y1: Data analysed-E (Som) | Z1: Data analysed-E (Germ) | AA1: Sample leveling | AB1: Analysis | AC1: Report (made/release)
B2: 2022-2025 | AB2: - | AC2: -
A3: 1 | B3: 6 | C3: 6 | D3: Sujay | E3: 50 | F3: Male | G3: NA | H3: CON | N3: - | O3: - | Q3: - | R3: Exhausted | S3: Done | T3: - | U3: Research | V3: Medgenome | W3: - | X3: 122.16 (18.44) | Y3: Yes | Z3: - | AA3: 6b | AB3: - | AC3: -
A4: 2 | B4: 9 | C4: 1A0027 | D4: Jyoti Pujari | E4: 45 | F4: Female | G4: J000019 | H4: CON | M4: - | N4: - | O4: - | Q4: 44698 | R4: Exhausted | S4: Done | T4: - | U4: Research | V4: Medgenome | W4: - | X4: 79.99 (12) | Y4: Yes | Z4: Yes | AA4: 9b | AB4: - | AC4: -
A5: 3 | B5: 11 | C5: 1A0029 | D5: Priya Parsekar | E5: >45 | F5: Female | G5: P000004 | H5: CON | M5: - | N5: - | O5: - | Q5: 44698 | R5: Exhausted | S5: Done | T5: - | U5: Research | V5: Medgenome | W5: - | X5: 81.29 (12.2) | Y5: Yes | Z5: Yes | AA5: 11b, 11d | AB5: - | AC5: -
A6: 4 | B6: 14 | C6: 1A0041 | D6: Neepa dalal | E6: 52 | F6: Female | G6: N000002 | H6: CON | M6: - | N6: Diabetes, Thyroid, Osteoporosis & Parents have diabetes, heart diseases and cancer | O6: - | Q6: 44701 | R6: Exhausted | S6: Done | T6: - | U6: Research | V6: Medgenome | W6: - | X6: 77.41 (11.6) | Y6: Yes | Z6: Yes | AA6: 14b, 14d | AB6: - | AC6: -
A7: 5 | B7: 24 | C7: 1A0061 | D7: Rita Gurwada | E7: 63 | F7: Female | G7: R000005 | H7: CON | M7: - | N7: - | O7: - | Q7: 44711 | R7: Exhausted | S7: Done | T7: 8.4 | U7: Research | V7: Medgenome | W7: - | X7: 59.75 (9) | Y7: Yes | Z7: Yes | AA7: 24b, 24d | AB7: - | AC7: -
A8: 6 | B8: 27 | C8: 1A0154 | D8: Kapil Agarwal | E8: 38 | F8: Male | G8: K000006 | H8: CON | M8: - | N8: T.N Breast Cancer (Mother) | O8: - | Q8: 44770 | R8: Exhausted | S8: Done | T8: 8.4 | U8: Research | V8: Medgenome | W8: - | X8: 56.16 (8.4) | Y8: Yes | Z8: Yes | AA8: 27b | AB8: - | AC8: -
A9: 7 | B9: 32 | C9: 1A0166 | D9: Leela E. Shinde | E9: 62 | F9: Female | G9: L000003 | H9: CON | M9: - | N9: - | O9: - | Q9: 44796 | R9: Exhausted | S9: Done | T9: 8.5 | U9: Research | V9: Medgenome | W9: - | X9: 73.19 (11) | Y9: Yes | Z9: Yes | AA9: 32b, 32d | AB9: - | AC9: -
A10: 8 | B10: 34 | C10: 1A0169 | D10: Nitu Kumari | E10: 35 | F10: Female | G10: N000010 | H10: CON | M10: - | N10: - | O10: - | Q10: 44798 | R10: Exhausted | S10: Done | T10: 8.3 | U10: Research | V10: Medgenome | W10: - | X10: 66.55 (10) | Y10: Yes | Z10: Yes | AA10: 34b, 34d | AB10: - | AC10: -
A11: 9 | B11: 36 | C11: 1A0168 | D11: Pramod Shinde | E11: 37 | F11: Male | G11: P000015 | H11: CON | M11: - | N11: Cancer-Family History | O11: - | Q11: 44796 | R11: Exhausted | S11: Done | T11: 8.6 | U11: Research | V11: Medgenome | W11: - | X11: 59.43 (8.8) | Y11: Yes | Z11: Yes | AA11: 36b | AB11: - | AC11: -
A12: 10 | B12: 37 | C12: 1A0159 | D12: Satish Shukla | E12: 35 | F12: Male | G12: S000040 | H12: CON | M12: - | N12: - | O12: - | Q12: 44781 | R12: Exhausted | S12: Done | T12: 8.2 | U12: Research | V12: Medgenome | W12: - | X12: 73.78 (11) | Y12: Yes | Z12: - | AA12: 37b | AB12: - | AC12: -
A13: 11 | B13: 38 | C13: 1A0155 | D13: Rohit Kachroo | E13: 50 | F13: Male | G13: R000010 | H13: CON | M13: - | N13: - | O13: - | Q13: - | R13: Exhausted | S13: Done | T13: 9.6 | U13: Research | V13: Medgenome | W13: - | X13: 75.18 (11.2) | Y13: Yes | Z13: Yes | AA13: 38b, 38d | AB13: - | AC13: -
A14: 12 | B14: 43 | C14: 1A0347 | D14: V Krishnan | E14: 52 | F14: Male | G14: K000017 | H14: CON | I14: Elevated PSA | M14: PSA high | N14: - | O14: - | Q14: - | R14: Exhausted | S14: Done | T14: 8.3 | U14: Report | V14: Medgenome | W14: - | X14: 72.92 (11) | Y14: Yes | Z14: Yes | AA14: 43b, 43d | AB14: - | AC14: -
A15: 13 | B15: 44 | C15: 1A0348 | D15: Aparna | E15: 55 | F15: Female | G15: A000045 | H15: CON | N15: - | O15: - | Q15: 44875 | R15: Exhausted | S15: Done | T15: 8.3 | U15: Research | V15: Medgenome | W15: - | X15: 53.31 (8) | Y15: Yes | Z15: Yes | AA15: 44b, 44d | AB15: - | AC15: -
A16: 14 | B16: 56 | C16: 1A0458 | D16: Gunjan Bajpai | E16: 42 | F16: Female | G16: G000012 | H16: CON | M16: - | N16: Diabetes | O16: - | Q16: 44905 | R16: YES | S16: Done | T16: 8.5 | U16: Research | V16: Medgenome | W16: - | X16: 39.11 (5.8) | Y16: Yes | Z16: Yes | AA16: 56b, 56d_R | AB16: - | AC16: -
A17: 15 | B17: 57 | C17: 1A0459 | D17: Amit Bajpai | E17: 47 | F17: Male | G17: A000054 | H17: CON | M17: - | N17: Diabetes | O17: - | Q17: 44905 | R17: YES | S17: Done | T17: 8.6 | U17: Research | V17: Medgenome | W17: - | X17: 87.84 (13.2) | Y17: Yes | Z17: Yes | AA17: 57b, 57d_R | AB17: - | AC17: -
A18: 16 | B18: 77 | C18: 2A0027 | D18: Meena Sawant | E18: 57 | F18: Female | G18: M000034 | H18: CON | M18: - | N18: - | O18: - | Q18: 44933 | R18: YES | S18: Done | T18: 8.8 | U18: Research | V18: Medgenome | W18: - | X18: 56.56 (8.4) | Y18: Yes | Z18: Yes | AA18: 77b, 77d | AB18: - | AC18: -
A19: 17 | B19: 91 | C19: 2A0087 | D19: Dr G. S. Toteja | E19: 64 | F19: Male | G19: T000013 | H19: CON | M19: - | N19: - | O19: - | Q19: 44942 | R19: YES | S19: Done | T19: 8.2 | U19: Research | V19: Medgenome | W19: - | X19: 103.48 () | Y19: Yes | Z19: Yes | AA19: 91b, 91d | AB19: - | AC19: -
A20: 18 | B20: 136 | C20: 2A0440 | D20: Neha Ajay Hirlekar | E20: 39 | F20: Female | G20: N000044 | H20: CON | M20: - | N20: Her Grandfather (mother side), Uncle (mother side) | O20: - | Q20: 0 | R20: YES | S20: Done | T20: - | U20: Research | V20: Medgenome | W20: 45076 | X20: 79.14 (11.8) | Y20: Yes | Z20: - | AA20: 136d/148d | AB20: - | AC20: -
A21: 19 | B21: 89 | C21: 2A0057 | D21: Amruta Ghag | E21: 62 | F21: Female | G21: A000062 | H21: CON | M21: - | N21: Diabetes and HTN; Mother- colon cancer; Brother-pancreas | O21: - | Q21: 44936 | R21: YES | S21: Done | T21: 8.3 | U21: Research | V21: Medgenome | W21: 45076 | X21: 68.68 (10.2) | Y21: Yes | Z21: Yes | AA21: - | AB21: - | AC21: -
A22: 20 | B22: 161 | C22: 2A0760 | D22: Radhika Radia | E22: 46 | F22: Female | G22: R000022 | H22: CON | M22: - | N22: Brother- Prostate Cancer | O22: - | Q22: 45145 | R22: YES | S22: Done | T22: 8.5 | U22: Research | V22: Medgenome | W22: 45169 | X22: 59.6 (8.8) | Y22: Yes | Z22: Yes | AA22: 161b, 161d | AB22: Yes | AC22: Released
A23: 21 | B23: 166 | C23: 2A1063 | D23: Ravikant Ruia | E23: 74 | F23: Male | G23: R000075 | H23: Benign | I23: Screening | K23: Male Reproductive Organ (Prostate, BPH), Multiple benign cystic lesions | L23: Prostate | M23: Adenomatous prostate hyperplasia with multiple benign cystic lesions | N23: Clinical history of patient - Adenomatous prostate hyperplasia with multiple benign cystic lesions (MRI, dated 23/1/218) and benign prostate hyperplasia (MRI, dated 14/9/219); Serum PSA: 1.16 ng/mL, dated 11/11/223; Serum cancer marker: AFP-α, CA15.3, CA19.9, CEA & Thyroglobulin (All in normal range), dated 11/11/223; On hormone therapy: past 2-3 years. Family history of cancer - Brother: Lung Cancer, Sister: Myelodysplastic syndrome, Sister: Cancer (type not provided)._x000D_ | O23: - | Q23: 45241 | R23: YES | S23: Done | T23: 8.5 | U23: Report | V23: Medgenome | W23: 45265 | X23: 61.67 (9.2) | Y23: Yes | Z23: Yes | AA23: 166b, 166d | AB23: Yes | AC23: Released
A24: 22 | B24: 167 | C24: 2A1100 | D24: Madhu Ruia | E24: 68 | F24: Female | G24: M000094 | H24: Benign | K24: Hepatobilliary System (Liver, Hemangioma) | L24: Liver | M24: - | N24: Clinical history of patient - Hemangioma in liver (Report not provided). On hormone therapy (Estrogen/Progesterone). Cancer serum marker done (Report not provided). Tonsillectomy at the age of 11/12 years. | O24: - | Q24: 45253 | R24: YES | S24: Done | T24: 8.9 | U24: Report | V24: Medgenome | W24: 45280 | X24: 78.99 (11.8) | Y24: Yes | Z24: Yes | AA24: 167b, 167d | AB24: - | AC24: -
A25: 23 | B25: 163 | C25: 2A0810 | D25: Bhavna Roy | E25: 56 | F25: Female | G25: B000032 | H25: CON | M25: - | N25: - | O25: - | Q25: 45161 | R25: YES | S25: Done | T25: 9.1 | U25: Research | V25: Medgenome | W25: 45183 | X25: 57.19 (8.6) | Y25: Yes | Z25: Yes | AA25: 163b, 163d | AB25: - | AC25: -
A26: 24 | B26: 189 | C26: 3A0326 | D26: Kavita Nalawade | E26: 25 | F26: Female | G26: K000010 | H26: CON | M26: - | N26: Father- cancer | O26: - | Q26: 45357 | R26: YES | S26: Done | T26: 8.9 (100X) | U26: Research | V26: Medgenome | W26: 45398 | X26: 61.28 (9.2) | Y26: Yes | Z26: - | AA26: 189b, 189d | AB26: Yes | AC26: Released
A27: 25 | B27: 19 | C27: 3A0350 | D27: Dheeraj Ahluwalia | E27: 56 | F27: Male | G27: D000071 | H27: Benign | I27: Enlarged prostate | M27: Diabetes, cholesterol, enlarged prostate | N27: Family history of cancer: Father - Brain cancer at 79 Years, Paternal Grandfather - Blood cancer at 78 Years; Other health conditions (Current Medications): Elevated cholesterol (Lipitor), Diabetes (Linagliptin, Empagliflozin, Glucophage XR), Enlarged prostrate (Tamsulosin Hydrochloride) | O27: - | Q27: 45369 | R27: YES | S27: Done | T27: 9.2 (250X) | U27: Report | V27: Medgenome | W27: 45411 | X27: 62.6 (9.4) | Y27: Yes | Z27: Yes | AA27: 190b, 190d | AB27: Yes | AC27: Released
A28: 26 | B28: 192 | C28: 3A0454 | D28: Mehar Bajaj | E28: 27 | F28: Female | G28: M000132 | H28: CON | M28: - | N28: Clinical history of patient: No relevant clinical history of concern. Family history of cancer: Maternal Grandfather - Lung cancer at age of 7 years, Maternal great grandfather and great grandmother - Ear cancer | O28: - | Q28: 45390 | R28: YES | S28: Done | T28: 8.7 (250X) | U28: Report | V28: Medgenome | W28: 45427 | X28: 156.79 (23.6) | Y28: Yes | Z28: Yes | AA28: 192b, 192d | AB28: - | AC28: -
A29: 27 | B29: 21 | C29: 3A0631 | D29: Nirali Gurwada | E29: 40 | F29: Female | G29: N000092 | H29: CON | M29: - | N29: - | O29: - | Q29: 45454 | R29: YES | S29: Done | T29: 8.2 (250X) | U29: Report | V29: Medgenome | W29: 45482 | X29: 193.85 (29.2) | Y29: Yes | Z29: Yes | AA29: 201b, 201d | AB29: Yes | AC29: Released
A30: 28 | B30: 24 | C30: 3A0700 | D30: Vijay Shah | E30: 67 | F30: Male | G30: V000001 | H30: CON | M30: Diabetes, hypertension | N30: Clinical history of patient • Diabetes and high BP in the last 1 year: On Rx drug for 4 months, now stopped. • Sudden transient rise in BP in working hours 4 months back, high CPK MB levels: 2 U/I in blood dated 17th Apr 224, HS troponin 1 level is in normal range dated 17th Apr 224 • Smoking since last 1 years: 2-3 per day and occasional drinking (stopped from the last 2 months) • Supplements: - Formula 1 from HERBALIFE - Personalised Protein powder, shakes, nutritional supplements, cell activator tablets (Antioxidant/ Alpha-lipoic acid tablet) as a meal replacement; Probiotics (Bacillus Coagulans) for gut health; XAR- XAP 2 times a day daily Family history of cancer • NA | O30: - | Q30: 45472 | R30: YES | S30: Done | T30: 8.6 (100X) | U30: Report | V30: Medgenome | W30: 45510 | X30: 69.62 (10.4) | Y30: Yes | Z30: Yes | AA30: 204b, 204d | AB30: - | AC30: -
A31: 29 | B31: 25 | C31: 3A0723 | D31: Shweta Devendra | E31: 26 | F31: Female | G31: S000411 | H31: CON | M31: - | N31: - | O31: - | Q31: 45478 | R31: YES | S31: Done | T31: 8.4 (100X) | U31: Research | V31: Medgenome | W31: 45516 | X31: 80.46 (12) | Y31: Yes | Z31: Yes | AA31: 205b, 205d | AB31: Yes | AC31: Released
A32: 30 | B32: 29 | C32: 3A0753 | D32: Shailesh HariBhakti | E32: 68 | F32: Male | G32: S000221 | H32: CON | M32: Diabetes, Heart disease | N32: Clinical History  Bypass surgery in 24, pacemaker in 222, both eyes cataract surgery  Diabetes-taking insulin (dose was titrating based on sugar level)  XAR-XAP for last 5 years (dose: during covid 3 times each/day, now once/day); Nova rapid bulds; Shelcal 5; Galvin met 5/5; Rozuvas cv Seloken XL 12.5 mg Family history of cancer  Mother- diabetes, cardiovascular problem | O32: - | Q32: 45484 | R32: YES | S32: Done | T32: 7.9 (250X) | U32: Report | V32: Medgenome | W32: 45511 | X32: 160.7 (24.2) | Y32: Yes | Z32: Yes | AA32: 209b, 209d | AB32: Yes | AC32: Released
A33: 31 | B33: 213 | C33: 3A0819 | D33: Niteen Tulpule | E33: 50 | F33: Male | G33: N000101 | H33: CON | M33: Hypertension | Q33: 45496 | R33: YES | S33: Done | T33: 8.4 (250X) | U33: Report | V33: Medgenome | W33: 45561 | X33: 132.77 (20) | Y33: Yes | Z33: Yes | AA33: 213b, 213d | AB33: - | AC33: -
A34: 32 | B34: 249 | C34: 3A1093 | D34: Kavita Singh | E34: 59 | F34: Female | G34: K000101 | H34: D | J34: Dr Nadeem | M34: - | Q34: 45587 | R34: YES | S34: Done | T34: 8.6 | U34: Report | V34: Medgenome | W34: 45624 | X34: 69.64 (10.4) | Y34: Yes | Z34: Yes | AA34: 249b, 249d | AB34: Yes | AC34: Released
A35: 33 | B35: 276 | C35: 3A1167 | D35: Mahesh Agrawal | E35: 73 | F35: Male | G35: M000008 | H35: Benign | K35: Male Reproductive Organ (Benign Prostate Hyperplasia), exophytic cyst in the upper pole of left kidney | L35: Prostate, kidney | M35: Hypothyroidism | Q35: 45610 | R35: YES | S35: Done | T35: - | U35: Paid Report | V35: Medgenome | W35: 45690 | X35: 155.86 (23.4) | Y35: Yes | Z35: Yes | AA35: 276b, 276d | AB35: - | AC35: -
A36: 34 | B36: 31 | C36: 3A1248 | D36: Ashish Gupta | E36: 26 | F36: Male | G36: A000300 | H36: D | J36: Dr Nadeem | M36: Diabetes | Q36: 45624 | R36: YES | S36: Done | T36: 9.1 | U36: Research | V36: Medgenome | W36: 45677 | X36: 79.48 (12) | Y36: Yes | Z36: Yes | AA36: 301b, 301d | AB36: Yes | AC36: Released
A37: 35 | B37: 322 | C37: 3A1288 | D37: Shiv Nayak | E37: 64 | F37: Male | G37: S000506 | H37: CON | M37: - | Q37: 45635 | R37: YES | S37: Done | T37: 7.9 | U37: Report | V37: Medgenome | W37: 45677 | X37: 63.6 (9.6) | Y37: Yes | Z37: Yes | AA37: 322b, 322d | AB37: Yes | AC37: Released
A38: 36 | B38: 359 | C38: 3A1342 | D38: Komal Dharmani | E38: 44 | F38: Female | G38: K000114 | H38: Benign | K38: Female Reproductive Organ (Endometriosis and Uterine Fibroids) | L38: Endometriosis and Uterine Fibroids | M38: Endometriosis, fibroid surgery in 2019 | Q38: 45645 | R38: YES | S38: Done | T38: 7.7 | U38: Report | V38: Medgenome | W38: 45692 | X38: 76.31 (11.4) | Y38: Yes | Z38: Yes | AA38: 359b, 359d | AB38: Yes | AC38: Released
A39: 37 | B39: 36 | C39: 3A1343 | D39: Lalit Dharmani | E39: 49 | F39: Male | G39: L000039 | H39: CON | M39: - | Q39: 45645 | R39: YES | S39: Done | T39: 8.2 | U39: Report | V39: Medgenome | W39: 45692 | X39: 66.55 (10) | Y39: Yes | Z39: Yes | AA39: 360b, 360d | AB39: - | AC39: -
A40: 38 | C40: 4A0414 | D40: Arun Madhu | E40: 40 | F40: Male | G40: A000355 | H40: CON | M40: Bradycardia, Sleep apnoea | Q40: 45717 | R40: YES | S40: Done | T40: - | U40: Research | V40: MiBiome | W40: 45832 | X40: 66.84 (10) | Y40: Yes | Z40: - | AA40: 4A0414 | AB40: - | AC40: -
...

Sheet exclusion
A1: Sr no | B1: AOB ID | C1: SID | D1: Name | E1: Age | F1: Gender | G1: Patient ID | H1: New Case label | I1: Additional | J1: Source | K1: Disease Type | L1: Comorbidity | M1: Family history | N1: Metastasis | O1: Patient status | P1: Sample collection date | Q1: DNA availability | R1: Sequencing | S1: DIN | T1: Research/Report | U1: Sequencing partner (E) | V1: Data received (E) | W1: TMR-E (Gbp) | X1: Data analysed-E (Som) | Y1: Sample leveling
B2: PD001 | E2: 4 | F2: Male
B3: PD002 | E3: 4 | F3: Male
B4: PD003 | E4: 4 | F4: Male
B5: PD004 | E5: 4 | F5: Female
B6: PD005 | E6: 11 | F6: Female
B7: PD006 | E7: 9 | F7: Female
B8: PD007 | E8: 5 | F8: Female
B9: PD008 | E9: 5 | F9: Female
B10: 58 | C10: 1A0460 | D10: Anay Bajpai | E10: 13 | F10: Male | G10: A000055 | H10: CON | L10: - | M10: - | N10: - | P10: 44905 | Q10: YES | R10: Done | S10: 8.6 | T10: Research | U10: Medgenome | V10: - | W10: 82.53 (12.4) | X10: Yes | Y10: 58b, 58d
B11: 74 | C11: 2A0002 | D11: Anika Tripathi | E11: 15 | F11: Female | G11: A000057 | H11: CON | L11: - | M11: - | N11: - | P11: 44929 | Q11: YES | R11: Done | S11: 8.2 | T11: Research | U11: Medgenome | V11: - | W11: 69.29 (10.4) | X11: Yes | Y11: 74b, 74d
B12: 75 | C12: 2A0003 | D12: Ashna Tripathi | E12: 11 | F12: Female | G12: A000058 | H12: CON | L12: - | M12: - | N12: - | P12: 44929 | Q12: YES | R12: Done | S12: 8.3 | T12: Research | U12: Medgenome | V12: - | W12: 76.03 (11.4) | X12: Yes | Y12: 75b, 75d
B13: 231 | C13: 3A0884 | D13: Daivik Motwani | E13: 10 | F13: Male | G13: D000087 | H13: D | J13: Dr Nadeem | K13: Type 1 Diabetes Mellitus | L13: Diabetes | P13: 45556 | Q13: YES | R13: Done | S13: 8.1 | T13: Report | U13: Medgenome | V13: 45593 | W13: 134.93 (20.2) | X13: Yes | Y13: 231b, 231d
C14: 4A0084 | D14: Mohd. Jawad Shaikh | E14: 17 | F14: Male | G14: M000192 | H14: D | J14: Dr Nadeem | K14: Diabetes | L14: Diabetes | P14: 45670 | Q14: YES | R14: Done | S14: - | T14: Research | U14: Mibiome | V14: 45947 | W14: 83.4 (12.4) | X14: Yes | Y14: 4A0084_T
C15: 3A0885 | D15: Dvit Motwani | E15: 10 | F15: Male | G15: D000088 | H15: CON | M15: #N/A | N15: #N/A | O15: #N/A | P15: #N/A | Q15: YES | R15: Done | T15: #N/A | U15: #N/A | V15: #N/A | W15: #N/A | X15: #N/A
B16: 2 | C16: 1A0013 | D16: Raj Tambe | E16: 32 | F16: Male | G16: R000001 | H16: CON | L16: - | M16: - | N16: - | P16: 44692 | Q16: Exhausted | R16: Done | S16: - | T16: Report | U16: Medgenome | V16: - | W16: 52.76 (7.8) | X16: Yes | Y16: 2b, 2d
B17: 82 | C17: 2A0028 | D17: Deepa Bhartiya | E17: 63 | F17: Female | G17: D000010 | H17: CON | I17: Screening | L17: Pre-Diabetes | M17: Hyperthyroid | N17: - | P17: 44935 | Q17: YES | R17: Done | S17: 8.5 | T17: Report | U17: Medgenome | V17: - | W17: 46.49 (7) | X17: Yes | Y17: -
B18: 125 | C18: 2A0333 | D18: Mahesh Agrawal | E18: 73 | F18: Male | G18: M000008 | H18: Benign | I18: Screening | K18: Benign Prostate Hyperplasia | L18: - | M18: Wife had triple negative breast cancer | N18: - | P18: 44975 | Q18: YES | R18: Done | S18: 8.5 | T18: Research | U18: Medgenome | V18: - | W18: 122.67 () | X18: Yes | Y18: 125b, 125d
B19: 165 | C19: 2A1022 | D19: Brijesh Kaushal | E19: 39 | F19: Male | G19: B000002 | H19: CON | L19: - | M19: - | N19: - | P19: 45224 | Q19: YES | R19: Done | S19: 8.4 | T19: Research | U19: Medgenome | V19: 45268 | W19: 59.64 (9) | X19: Yes | Y19: 165b, 165d
B20: 158 | C20: 2A0729 | D20: Mitansh Tripathi | E20: 27 | F20: Male | G20: M000073 | H20: CON | L20: - | M20: - | N20: - | P20: 45132 | Q20: YES | R20: Done | S20: 8.9 | T20: Research | U20: Medgenome | V20: 45155 | W20: 64.02 (9.6) | X20: Yes | Y20: 158b, 158d
B21: 18 | C21: 3A0017 | D21: Anish Tripathi | E21: 55 | F21: Male | G21: A000004 | H21: CON | L21: - | M21: - | N21: - | P21: 45294 | Q21: YES | R21: Done | S21: 8.2 | T21: Research | U21: Medgenome | V21: 45323 | W21: 70.68 () | X21: Yes | Y21: 180b, 180d
B22: 181 | C22: 3A0032 | D22: Ashish Tripathi | E22: 49 | F22: Male | G22: A000033 | H22: Benign | K22: Hepatobilliary System (Fatty Liver) | L22: - | M22: - | N22: - | P22: 45297 | Q22: YES | R22: Done | S22: 8.7 | T22: Research | U22: Medgenome | V22: 45323 | W22: 65.06 () | X22: Yes | Y22: 181b, 181d
B23: 182 | C23: 3A0033 | D23: Amish Tripathi | E23: 49 | F23: Male | G23: A000028 | H23: CON | L23: - | M23: - | N23: - | P23: 45297 | Q23: YES | R23: Done | S23: 8.2 | T23: Research | U23: Medgenome | V23: 45323 | W23: 80.23 () | X23: Yes | Y23: 182b, 182d
B24: 183 | C24: 3A0034 | D24: Usha Tripathi | E24: 79 | F24: Female | G24: U000020 | H24: CON | I24: Screening | L24: Diabetes | M24: - | N24: - | P24: 45297 | Q24: YES | R24: Done | S24: 9.1 | T24: Research | U24: Medgenome | V24: 45323 | W24: 56.04 () | X24: Yes | Y24: 183b, 183d
B25: 212 | C25: 3A0816 | D25: Meeta Tripathi | E25: 52 | F25: Female | G25: M000013 | H25: CON | L25: - | P25: 45497 | Q25: YES | R25: Done | S25: 8.4 (250X) | T25: Report | U25: Medgenome | V25: 45530 | W25: 137.88 (20.8) | X25: Yes | Y25: 212b, 212d
C26: 4A1118 | D26: Zarien Khan | E26: 42 | F26: Female | G26: Z000008 | H26: D | J26: Dr Nadeem | P26: 45891 | Q26: YES | R26: Done | S26: - | T26: Research | U26: Mibiome | V26: 45933 | W26: 92.58 (13.8) | X26: Yes | Y26: 4A1118_T_MB_S24, 4A1118_E_MB_S41
C27: 4A0922 | D27: Pankaj Mehra | E27: 64 | F27: Male | G27: P000183 | H27: D | J27: Dr Nadeem | P27: 45847 | Q27: YES | R27: Done | S27: - | T27: Research | U27: MiBiome | V27: 45918 | W27: 72.35 (10.8) | X27: Not analysed | Y27: 4A0922_T_MB_S10, 4A0922_E_MB_S52
C28: 4A0500 | D28: Neelam Shinde | E28: 38 | F28: Female | G28: N000009 | H28: CON | P28: 45754 | Q28: YES | R28: Done | S28: - | T28: Research | U28: Mibiome | V28: 45947 | W28: 78.01 (11.6) | X28: Yes | Y28: 4A0500_E_MB_S34
C29: 4A0581 | D29: Padma Uttakar | E29: 46 | F29: Female | G29: P000002 | H29: CON | P29: 45769 | Q29: YES | R29: Done | S29: - | T29: Research | U29: Mibiome | V29: 45947 | W29: 74.24 (11.2) | X29: Yes | Y29: 4A0581_E_MB_S47
C30: 4A0529 | D30: Swaraj Mule | E30: 23 | F30: Male | G30: S000395 | H30: CON | P30: 45758 | Q30: YES | R30: Done | S30: - | T30: Research | U30: Mibiome | V30: 45947 | W30: 79.62 (12) | X30: Yes | Y30: 4A0529_E_MB_S42
B31: 175_S37 | C31: 4A0447 | D31: Chirag Dewan | E31: 38 | F31: Male | G31: C000044 | H31: CON | L31: - | P31: 45735 | Q31: YES | R31: Done | S31: - | T31: Research | U31: Mibiome | V31: 45947 | W31: 91.03 (13.6) | X31: Yes | Y31: 00175_S37
C32: 4A0530 | D32: Ankit Bhat | E32: 32 | F32: Male | G32: A000016 | H32: CON | P32: 45758 | Q32: YES | R32: Done | S32: - | T32: Research | U32: Mibiome | V32: 45947 | W32: 76.45 (11.4) | X32: Yes | Y32: 4A0530_E_MB_S43
B33: 26 | C33: 3A0724 | D33: Saba Khan | E33: 55 | F33: Female | G33: S000314 | H33: HR | I33: Suspected plasma cell disorder. | L33: High Risk | M33: • Suspected plasma cell disorder. • Increased IgG, free kappa light chain, and kappa/lambda ratio over the past seven months. • Serum creatinine, blood urea and serum calcium are within normal range. • 18th July 224: Elevated levels of serum IgG (24mgs/dl), kappa light chain (17.26mg/L), and kappa lambda ratio (2.19mg/L); mildly elevated (not significantly) beta-2 microglobulin; erythrocyte sedimentation rate within normal range. • The albumin-to-globulin ratio has exceeded the normal range since January 224. Gamma globulin gradually increased from 17.9 (A/G-1.51 on 23/1/24) to 16.6 (A/G- 2.2 on 19/3/24) to 2.7 (A/G- 1.25 on 16/7/24) Family history of cancer/other pathology • Uncle's son had cancer at age 65 years (type not known) • Father- diabetic and cardiac issue • Mother- Age related dementia | N33: - | P33: 45479 | Q33: YES | R33: Done | S33: 8.7 (250X) | T33: Report | U33: Medgenome | V33: 45510 | W33: 131.6 (19.8) | X33: Yes | Y33: 206b, 206d
C34: 4A0674 | D34: Santosh Kamble | E34: 33 | F34: Male | G34: S000003 | H34: CON | P34: 45799 | Q34: YES | R34: Done | S34: - | T34: Research | U34: MiBiome | V34: 45918 | W34: 57.52 (8.6) | X34: Not analysed | Y34: 4A0674_E_MB_S56
B35: 13 | C35: 1A0086 | D35: Bindu Madhav Joshi | E35: >45 | F35: Male | G35: B000003 | H35: COT | K35: B-Cell Non-Hodkgins Lymphoma | L35: - | M35: - | N35: - | P35: 44718 | Q35: Exhausted | R35: Done | S35: - | T35: Research | U35: Medgenome | V35: - | W35: 72.2 (10.8) | X35: Yes | Y35: 13b
B36: 195 | C36: 3A0467 | D36: Anita Sanap | E36: 54 | F36: Female | G36: A000094 | H36: COT | K36: Cervical cancer | L36: - | M36: Clinical history of patient: Diagnosis: Metastatic carcinoma of cervix with bone mets and obstructive uropathy, HPR: Keratinizing squamous cell carcinoma; Stage IV; grade II. Treatment received and follow up: 6 cycles Nab-Paclitaxel + Carboplatin + Bevacizumab (23/2/223- 16/6/223), 3 cycles of maintenance therapy with Bevacizumab (8/7/223-19/8/223). PET scan shows disease progression in Sep 223, 6 cycles Nab-Paclitaxel + Bevacizumab (LD: Nov 223), PET scan shows disease progression in Nov 223, 6 cycles of KEYTRUDA (LD: 25/11/223-15/3/223), 5 cycles of radiotherapy (LD 21/2/224)- developed haematuria. PET scan shows significant increase in size and metabolic activity of the cervical mass extending to uterus involving the urinary bladder, parametrium, bilateral VUJ and rectum. Increase in size and activity of abdomino-pelvic lymph nodes and new involvement of multiple liver and osteolytic skeletal lesions suggesting disease progression. There is mild increase in the metabolic activity of left kidney with mild urothelial enhancement. (performed on 2/4/224). Other health conditions: Arthritis | N36: - | O36: Deceased | P36: 45397 | Q36: YES | R36: Done | S36: 8.6 (250X) | T36: Report | U36: Medgenome | V36: 45435 | W36: 178.52 (26.8) | X36: Yes | Y36: 195b, 195d
B37: 216 | C37: 3A0860 | D37: Joshitha Sudhir | E37: 50 | F37: Female | G37: J000048 | H37: COT | K37: Adenocarcinoma upper rectum | L37: - | P37: 45539 | Q37: YES | R37: repeat | S37: 7.8 | T37: Report | U37: Medgenome | V37: 45594 | W37: 183.54 (27.6) | X37: Yes | Y37: 216b, 216d
B38: 253 | C38: 3A1108 | D38: Rekha Saboo | E38: 75 | F38: Female | G38: R000196 | H38: COT | K38: Perianal squamous cell carcinoma | L38: - | P38: 45600 | Q38: YES | R38: Done | S38: 7.7 | T38: Report | U38: Medgenome | V38: 45665 | W38: 118.38 (17.8) | X38: Yes | Y38: 253b, 253d
C39: 4A0349 | D39: Rekha Saboo | E39: 75 | F39: Female | G39: R000196 | H39: COT | K39: Perianal squamous cell carcinoma | L39: - | P39: 45699 | Q39: YES | R39: Done | S39: - | T39: Report | U39: MiBiome | V39: 45747 | W39: 85.70 (12.8) | X39: Yes | Y39: 4A0349_T
B40: 92 | C40: 2A0090 | D40: Athira Nair | E40: 26 | F40: Female | G40: A000021 | H40: CS | K40: Follicular Ameloblastoma | L40: - | M40: - | N40: - | P40: 44943 | Q40: YES | R40: Done | S40: 8.2 | T40: Research | U40: Medgenome | V40: - | W40: 81.55 () | X40: Yes | Y40: 92b, 92d
...

Sheet CONTROL
A1: Sample | B1: Age (1-30) | D1: Sample | E1: Age (30-60) | G1: Sample | H1: Age (60+)
A2: 3A0326 | B2: 25 | D2: 6 | E2: 50 | G2: 1A0061 | H2: 63
A3: 3A0454 | B3: 27 | D3: 1A0027 | E3: 45 | G3: 1A0166 | H3: 62
A4: 3A0723 | B4: 26 | D4: 1A0041 | E4: 52 | G4: 2A0087 | H4: 64
A5: 4A0492 | B5: 18 | D5: 1A0154 | E5: 38 | G5: 2A0057 | H5: 62
A6: 4A0122 | B6: 30 | D6: 1A0169 | E6: 35 | G6: 3A0700 | H6: 67
A7: 4A1114 | B7: 22 | D7: 1A0168 | E7: 37 | G7: 3A0753 | H7: 68
A8: 4A0603 | B8: 22 | D8: 1A0159 | E8: 35 | G8: 3A1288 | H8: 64
A9: 4A0431 | B9: 23 | D9: 1A0155 | E9: 50 | G9: 3A1081 | H9: 77
A10: 4A0430 | B10: 23 | D10: 1A0347 | E10: 52 | G10: 4A0607 | H10: 70
A11: 4A0460 | B11: 23 | D11: 1A0348 | E11: 55 | G11: 4A0857 | H11: 76
A12: 4A0432 | B12: 25 | D12: 1A0458 | E12: 42 | G12: 4A0179 | H12: 76
A13: 4A0576 | B13: 29 | D13: 1A0459 | E13: 47 | G13: 4A0181 | H13: 64
A14: 4A0526 | B14: 24 | D14: 2A0027 | E14: 57 | G14: 4A0202 | H14: 72
... A55: 3A0725 | B55: 23 | D55: 4A0309 | E55: 33 | G55: 5A0183 | H55: 70
A56: 3A0726 | B56: 18 | D56: 4A0602 | E56: 36
A57: 3A0834 | B57: 20 | D57: 4A0511 | E57: 57
A58: 3A0853 | B58: 20 | D58: 4A0528 | E58: 32
A59: 3A1326 | B59: 28 | D59: 4A0506 | E59: 45
A60: 3A1335 | B60: 24 | D60: 1A0035 | E60: 53
A61: 3A1338 | B61: 21 | D61: 2A0809 | E61: 50
A62: 4A0012 | B62: 19 | D62: 3A1071 | E62: 42
A63: 4A0013 | B63: 27 | D63: 3A1205 | E63: 33
A64: 4A0031 | B64: 23 | D64: 4A0150 | E64: 41
A65: 4A0033 | B65: 29 | D65: 4A0136 | E65: 33
A66: 4A0040 | B66: 29 | D66: 4A1009 | E66: 53
A67: 4A0042 | B67: 22 | D67: 4A0178 | E67: 39
... A120: 5A0158 | B120: 25 | D120: 4A1234 | E120: 58
D121: 4A1412 | E121: 57
D122: 4A1439 | E122: 37
D123: 4A1441 | E123: 59
D124: 4A1533 | E124: 47
D125: 2A0668 | E125: 40
D126: 3A0713 | E126: 32
D127: 3A0705 | E127: 31
D128: 3A0706 | E128: 34
D129: 3A0707 | E129: 33
D130: 3A0708 | E130: 32
D131: 3A0714 | E131: 32
D132: 3A0716 | E132: 35
...

Sheet COT
A1: Sample | B1: Age(1-30) | D1: Sample | E1: Age(30-60) | G1: Sample | H1: Age(60+)
A2: 1A0157 | B2: 29 | D2: 1A0162 | E2: 43 | G2: 4A0725 | H2: 73
A3: 1A0258 | B3: 26 | D3: 2A0214 | E3: 39 | G3: 1A0044 | H3: 86
A4: 2A0191 | B4: 26 | D4: 5 | E4: 60 | G4: 1A0422 | H4: 62
A5: 1A0429 | B5: 21 | D5: 1A0156 | E5: 48 | G5: 1A0436 | H5: 72
D6: 1A0329 | E6: 58 | G6: 1A0466 | H6: 70
D7: 1A0388 | E7: 38 | G7: 1A0474 | H7: 65
D8: 1A0424 | E8: 52 | G8: 1A0447 | H8: 71
D9: 1A0506 | E9: 52 | G9: 1A0525 | H9: 70
D10: 2A0094 | E10: 59 | G10: 2A0049 | H10: 72
D11: 2A0097 | E11: 36 | G11: 2A0098 | H11: 75
D12: 2A0157 | E12: 38 | G12: 2A0115 | H12: 75
D13: 2A0169 | E13: 49 | G13: 2A0127 | H13: 69
D14: 2A0187 | E14: 52 | G14: 2A0166 | H14: 65
D15: 2A0202 | E15: 57 | G15: 2A0185 | H15: 72
D16: 2A0334 | E16: 59 | G16: 2A0203 | H16: 71
D17: 3A0074 | E17: 54 | G17: 2A0293 | H17: 65
... D32: 4A1052 | E32: 43 | G32: 3A0407 | H32: 72
D33: 4A1643 | E33: 52 | G33: 4 | H33: 65
D34: 1A0431 | E34: 46 | G34: 4A0153 | H34: 79
D35: 1A0437 | E35: 50 | G35: 4A1339 | H35: 70
D36: 1A0446 | E36: 53 | G36: 4A1446 | H36: 78
D37: 1A0450 | E37: 53 | G37: 2A0010 | H37: 65
G38: 1A0452 | H38: 62
G39: 1A0469 | H39: 68
G40: 1A0477 | H40: 62

Sheet CTN
A1: Sample | B1: Age(1-30) | D1: Sample | E1: Age (30-60) | G1: Sample | H1: Age(60+)
A2: 2A0319 | B2: 27 | D2: 1A0478 | E2: 55 | G2: 2A0004 | H2: 74
A3: 3A0850 | B3: 27 | D3: 1A0486 | E3: 41 | G3: 2A0168 | H3: 69
D4: 2A0126 | E4: 48 | G4: 2A0335 | H4: 61
D5: 2A0144 | E5: 31 | G5: 2A1172 | H5: 64
D6: 2A0263 | E6: 45 | G6: 3A0814 | H6: 62
D7: 2A0270 | E7: 40 | G7: 3A0861 | H7: 76
D8: 2A0287 | E8: 42 | G8: 3A1291 | H8: 77
D9: 2A0305 | E9: 57 | G9: 3A1253 | H9: 67
D10: 2A0330 | E10: 41 | G10: 3A1264 | H10: 72
D11: 2A0373 | E11: 52 | G11: 3A1270 | H11: 71
D12: 2A0593 | E12: 52 | G12: 3A1280 | H12: 70
D13: 1A0518 | E13: 38 | G13: 3A1301 | H13: 68
D14: 2A0662 | E14: 44 | G14: 3A1305 | H14: 64
D15: 2A1171 | E15: 44 | G15: 3A1321 | H15: 61
... D47: 1A0463 | E47: 42 | G47: 5A0261 | H47: 65
D48: 4A1559 | E48: 46
D49: 4A1740 | E49: 43
D50: 4A1600 | E50: 42
D51: 4A1618 | E51: 60
D52: 4A1992 | E52: 43
D53: 5A0257 | E53: 37
D54: 5A0260 | E54: 45

Sheet CS
A1: Sample | B1: Age(1-30) | D1: Sample | E1: Age(30-60) | G1: Sample | H1: Age(60+)
A2: 1A0449 | B2: 22 | D2: 4A0383 | E2: 32 | G2: 1A0487 | H2: 66
A3: 2A0153 | B3: 27 | D3: 3A0740 | E3: 53 | G3: 3A0229 | H3: 67
A4: 2A1158 | B4: 26 | D4: 8 | E4: 55 | G4: 1A0375 | H4: 72
A5: 1A0099 | B5: 26 | D5: 1A0136 | E5: 49 | G5: 2A0005 | H5: 66
D6: 1A0457 | E6: 48 | G6: 2A0292 | H6: 61
D7: 1A0476 | E7: 44 | G7: 2A0301 | H7: 72
D8: 2A0290 | E8: 33 | G8: 2A0635 | H8: 61
D9: 2A0336 | E9: 54 | G9: 2A0737 | H9: 69
D10: 2A0705 | E10: 55 | G10: 3A0060 | H10: 63
D11: 2A0370 | E11: 50 | G11: 3A1150 | H11: 72
D12: 2A0399 | E12: 53 | G12: 3A0721 | H12: 65
D13: 4A1100 | E13: 60 | G13: 4A0450 | H13: 72
D14: 3A0064 | E14: 32 | G14: 4A1653 | H14: 73
D15: 4A0115 | E15: 35 | G15: 4A0303 | H15: 69
D16: 4A1433 | E16: 49 | G16: 3A1085 | H16: 75
D17: 4A1705 | E17: 53 | G17: 4A0654 | H17: 71
D18: 4A0441 | E18: 52 | G18: 2A1235 | H18: 73
D19: 3A0855 | E19: 41
D20: 4A1617 | E20: 55

Sheet Cohort
AN4: ``````````````````````````````````````````````````````
B5: Mibiome | C5: \\10.10.2.7\Genome-Data\Mibiome\2025\Pipeline_results | AE5: 1A0133 | AF5: CAN | AG5: case level not known | AH5: 1A0093 | AI5: CAN | AJ5: case level not known
A6: Mibiome | B6: \\10.10.2.7\Genome-Data\Mibiome\2025\Pipeline_results | AD6: 1A0133 | AE6: CAN | AF6: case level not known | AG6: 1A0093 | AH6: CAN | AI6: case level not known
A7: Medgenome | B7: \\EPIGENERESLABS\MedGenome\AOBOnco_data analysis\Exome_Results\NGS_FE_Results_EBPL\Exome somatic re-run_FEB13 | AD7: 1A0364 | AE7: CAN | AF7: case level not known | AG7: 1A0161 | AH7: CAN | AI7: case level not known
AD8: 1A0383 | AE8: CAN | AF8: case level not known | AG8: 1A0163 | AH8: CAN | AI8: case level not known
A10: CONTROLS=257 | K10: CTN=77 | U10: COT=67 | AE10: CS=42 | AN10: HR= 20 | AW10: Benign | BF10: DIABETES=71
A11: Sr.no | B11: AOB ID | C11: SAMPLE ID | D11: NAME | E11: AGE | F11: Gender | G11: EXOME RE-RUN BY APARNA | H11: GB (OG/TD) | K11: Sr.no | L11: AOB ID | M11: SAMPLE ID | N11: NAME | O11: AGE | P11: Gender | Q11: EXOME RE-RUN BY APARNA | R11: GB (OG/TD) | U11: Sr.no | V11: AOB ID | W11: SAMPLE ID | X11: NAME | Y11: AGE | Z11: Gender | AA11: EXOME RE-RUN BY APARNA | AB11: GB (OG/TD) | AE11: Sr.no | AF11: AOB ID | AG11: SAMPLE ID | AH11: NAME | AI11: AGE | AJ11: Gender | AK11: EXOME RE-RUN BY APARNA | AL11: GB (OG/TD) | AN11: Sr.no | AO11: AOB ID | AP11: SAMPLE ID | AQ11: NAME | AR11: AGE | AS11: Gender | AT11: EXOME RE-RUN BY APARNA | AU11: GB (OG/TD) | AW11: Sr.no | AX11: AOB ID | AY11: SAMPLE ID | AZ11: NAME | BA11: AGE | BB11: Gender | BC11: EXOME RE-RUN BY APARNA | BD11: GB (OG/TD) | BF11: Sr.no | BG11: AOB ID | BH11: SAMPLE ID | BI11: NAME | BJ11: AGE | BK11: Gender | BL11: EXOME RE-RUN BY APARNA | BM11: GB (OG/TD)
A12: 1 | B12: 6 | C12: 6 | D12: Sujay | E12: 50 | F12: Male | H12: 122.16 (18.44) | K12: 1 | L12: 61 | M12: 1A0478 | N12: Bharatbai Kamble | O12: 55 | P12: Female | R12: 71.26 (10.6) | U12: 1 | W12: 4A0725 | X12: Suryakant Dabilkar | Y12: 73 | Z12: Male | AB12: 66.22 (9.8) | AE12: 1 | AG12: 4A0383 | AH12: Soumya Sahoo | AI12: 32 | AJ12: Male | AL12: 84.56 (12.6) | AN12: 1 | AO12: 144 | AP12: 2A0623 | AQ12: V Krishnan | AR12: 50 | AS12: Male | AU12: 70.34 (10.6) | AW12: 1 | AX12: 166 | AY12: 2A1063 | AZ12: Ravikant Ruia | BA12: 74 | BB12: Male | BD12: 61.67 (9.2) | BF12: 1 | BG12: 249 | BH12: 3A1093 | BI12: Kavita Singh | BJ12: 59 | BK12: Female | BM12: 69.64 (10.4)
